Workbook
Name MonthList: 'Setting sheet'!$E$3:$E$8
Name nrSemesterEnd: 'Setting sheet'!$C$4
Name nrsemesterstart: 'Setting sheet'!$C$3

Sheet DASHBOARD
AC1: Total Days | AD1: Working | AE1: =D14 -> 21
D2: Days Until | AC2: {=ROWS( _xlfn._xlws.FILTER(_xlfn.ANCHORARRAY( 'Main Database'!B4), MONTH(_xlfn.ANCHORARRAY('Main Database'!B4))=MONTH(DATEVALUE(DASHBOARD!D9&" 1")) ) )} -> 31 | AD2: Non-Working | AE2: =AC2-AE1 -> 10
B3: Today | C3: Current Week | D3: Mid-Sem Break | E3: Winter Break | G3: Semester Progress | O3: Upcoming Holidays
B4: =TODAY() -> 46236 | C4: {=_xlfn.XLOOKUP(B4,_xlfn.ANCHORARRAY('Main Database'!B4),_xlfn.ANCHORARRAY('Main Database'!D4))} -> 1 | D4: =ABS('Non-Working Days'!C11-DASHBOARD!B4) -> 96 | E4: =ABS(nrSemesterEnd-DASHBOARD!B4) -> 130 | G4: =MAX(0,MIN(1,(B4-nrsemesterstart)/(nrSemesterEnd-nrsemesterstart))) -> 0.044117647 | O4: Holiday | P4: Date
O5: {=IFERROR(_xlfn.TAKE(_xlfn._xlws.SORT(_xlfn._xlws.FILTER('Non-Working Days'!B3:C21,'Non-Working Days'!C3:C21>DASHBOARD!B4),2,1),3),"No Upcoming Events")} -> Independence Day | P5: 46249
O6: Janmashtami | P6: 46269
O7: Mahatma Gandhi's Birthday | P7: 46297
B9: Select Month | D9: August
D12: Working Days | H12: Holidays
D14: {=SUM(--_xlfn._xlws.FILTER(_xlfn.ANCHORARRAY('Main Database'!E4),MONTH(_xlfn.ANCHORARRAY('Main Database'!B4))=MONTH(DATEVALUE(DASHBOARD!D9&" 1"))))} -> 21 | H14: {=SUM(--((MONTH(_xlfn.ANCHORARRAY('Main Database'!B4))=MONTH(DATEVALUE(DASHBOARD!D9&" 1")))* (_xlfn.ANCHORARRAY('Main Database'!F4)<>"") ))} -> 1
E18: Weekends
E20: {=IFERROR(ROWS( _xlfn._xlws.FILTER(_xlfn.ANCHORARRAY( 'Main Database'!C4), (MONTH(_xlfn.ANCHORARRAY('Main Database'!B4))=MONTH(DATEVALUE(DASHBOARD!D9&" 1"))) *( (_xlfn.ANCHORARRAY('Main Database'!C4)="Sat") + (_xlfn.ANCHORARRAY('Main Database'!C4)="Sun")) )),0)} -> 10

Sheet Monthly Planner
B5: Select Month | C5: August | E5: Calendar View
E6: Mon | F6: Tue | G6: Wed | H6: Thu | I6: Fri | J6: Sat | K6: Sun
E7: {=_xlfn.LET( _xlpm.Data,_xlfn.ANCHORARRAY(E15), _xlpm.Dates,_xlfn.CHOOSECOLS(_xlpm.Data,1), _xlpm.Weeks,_xlfn.CHOOSECOLS(_xlpm.Data,3), _xlpm.StartWeek,MIN(_xlpm.Weeks), _xlpm.MonthNum,MONTH($E$15), _xlfn.MAKEARRAY( 6, 7, _xlfn.LAMBDA(_xlpm.r,_xlpm.c, IFERROR( _xlfn.XLOOKUP( 1, (_xlpm.Weeks=_xlpm.StartWeek+_xlpm.r-1)* (WEEKDAY(_xlpm.Dates,2)=_xlpm.c)* (MONTH(_xlpm.Dates)=_xlpm.MonthNum), _xlpm.Dates ), "" ) ) ) )} | J7: 46235 | K7: 46236
E8: 46237 | F8: 46238 | G8: 46239 | H8: 46240 | I8: 46241 | J8: 46242 | K8: 46243
E9: 46244 | F9: 46245 | G9: 46246 | H9: 46247 | I9: 46248 | J9: 46249 | K9: 46250
E10: 46251 | F10: 46252 | G10: 46253 | H10: 46254 | I10: 46255 | J10: 46256 | K10: 46257
E11: 46258 | F11: 46259 | G11: 46260 | H11: 46261 | I11: 46262 | J11: 46263 | K11: 46264
E12: 46265
E14: Date | F14: Day | G14: Semester Week | H14: Is Working day | I14: Holiday Name | J14: Event Type | K14: Event Name | N14: Monthly Overview
E15: {=_xlfn._xlws.FILTER(_xlfn.HSTACK(_xlfn.ANCHORARRAY('Main Database'!B4),_xlfn.ANCHORARRAY('Main Database'!C4),_xlfn.ANCHORARRAY('Main Database'!D4),_xlfn.ANCHORARRAY( 'Main Database'!E4),_xlfn.ANCHORARRAY( 'Main Database'!F4),_xlfn.ANCHORARRAY( 'Main Database'!G4),_xlfn.ANCHORARRAY( 'Main Database'!H4)),MONTH(_xlfn.ANCHORARRAY('Main Database'!B4))=_xlfn.XLOOKUP(C5,TblMonth[Months],TblMonth[Month Number]),"")} -> 46235 | F15: Sat | G15: 1 | H15: FALSE | N15: Total Days | O15: =COUNT(_xlfn.CHOOSECOLS(_xlfn.ANCHORARRAY(E15),1)) -> 31
E16: 46236 | F16: Sun | G16: 1 | H16: FALSE | N16: Working Days | O16: {=SUM(--_xlfn.CHOOSECOLS(_xlfn.ANCHORARRAY(E15),4))} -> 21
E17: 46237 | F17: Mon | G17: 2 | H17: TRUE | N17: Weekends | O17: {=SUM(--(WEEKDAY(INDEX(_xlfn.ANCHORARRAY(E15),0,1),2)>5))} -> 10
E18: 46238 | F18: Tue | G18: 2 | H18: TRUE | N18: Holidays | O18: {=SUM(--(_xlfn.CHOOSECOLS(_xlfn.ANCHORARRAY(E15),5)<>""))} -> 1
E19: 46239 | F19: Wed | G19: 2 | H19: TRUE | N19: Events | O19: {=SUM(--(_xlfn.CHOOSECOLS(_xlfn.ANCHORARRAY(E15),7)<>""))} -> 0
E20: 46240 | F20: Thu | G20: 2 | H20: TRUE
E21: 46241 | F21: Fri | G21: 2 | H21: TRUE
E22: 46242 | F22: Sat | G22: 2 | H22: FALSE
E23: 46243 | F23: Sun | G23: 2 | H23: FALSE
E24: 46244 | F24: Mon | G24: 3 | H24: TRUE
E25: 46245 | F25: Tue | G25: 3 | H25: TRUE
E26: 46246 | F26: Wed | G26: 3 | H26: TRUE
E27: 46247 | F27: Thu | G27: 3 | H27: TRUE
E28: 46248 | F28: Fri | G28: 3 | H28: TRUE
E29: 46249 | F29: Sat | G29: 3 | H29: FALSE | I29: Independence Day
E30: 46250 | F30: Sun | G30: 3 | H30: FALSE
E31: 46251 | F31: Mon | G31: 4 | H31: TRUE
E32: 46252 | F32: Tue | G32: 4 | H32: TRUE
E33: 46253 | F33: Wed | G33: 4 | H33: TRUE
E34: 46254 | F34: Thu | G34: 4 | H34: TRUE
E35: 46255 | F35: Fri | G35: 4 | H35: TRUE
E36: 46256 | F36: Sat | G36: 4 | H36: FALSE
E37: 46257 | F37: Sun | G37: 4 | H37: FALSE
E38: 46258 | F38: Mon | G38: 5 | H38: TRUE
E39: 46259 | F39: Tue | G39: 5 | H39: TRUE
E40: 46260 | F40: Wed | G40: 5 | H40: TRUE
E41: 46261 | F41: Thu | G41: 5 | H41: TRUE
... E45: 46265 | F45: Mon | G45: 6 | H45: TRUE

Sheet Main Database
B3: Date | C3: Day | D3: Semester Week | E3: Is Working day | F3: Holiday Name | G3: Event Type | H3: Event Name
B4: {=_xlfn.SEQUENCE(nrSemesterEnd-nrsemesterstart+1,1,nrsemesterstart,1)} -> 46230 | C4: {=TEXT(_xlfn.ANCHORARRAY(B4),"ddd")} -> Mon | D4: {=INT((_xlfn.ANCHORARRAY(B4)-nrsemesterstart)/7)+1} -> 1 | E4: {=IF(((_xlfn.ANCHORARRAY(C4)="Sat")+(_xlfn.ANCHORARRAY(C4)="Sun")+(_xlfn.ANCHORARRAY(F4)<>""))>0,FALSE,TRUE)} -> TRUE | F4: {=_xlfn.XLOOKUP(_xlfn.ANCHORARRAY(B4),TblNonWorkingDays[Date],TblNonWorkingDays[Name],"")} | G4: {=_xlfn.XLOOKUP(_xlfn.ANCHORARRAY(B4),TblEvents[DATE],TblEvents[Event Type],"")} | H4: {=_xlfn.XLOOKUP(_xlfn.ANCHORARRAY(B4),TblEvents[DATE],TblEvents[Event Name],"")}
B5: 46231 | C5: Tue | D5: 1 | E5: TRUE
B6: 46232 | C6: Wed | D6: 1 | E6: TRUE
B7: 46233 | C7: Thu | D7: 1 | E7: TRUE
B8: 46234 | C8: Fri | D8: 1 | E8: TRUE
B9: 46235 | C9: Sat | D9: 1 | E9: FALSE
B10: 46236 | C10: Sun | D10: 1 | E10: FALSE
B11: 46237 | C11: Mon | D11: 2 | E11: TRUE
B12: 46238 | C12: Tue | D12: 2 | E12: TRUE
B13: 46239 | C13: Wed | D13: 2 | E13: TRUE
B14: 46240 | C14: Thu | D14: 2 | E14: TRUE
B15: 46241 | C15: Fri | D15: 2 | E15: TRUE
B16: 46242 | C16: Sat | D16: 2 | E16: FALSE
... B22: 46248 | C22: Fri | D22: 3 | E22: TRUE
B23: 46249 | C23: Sat | D23: 3 | E23: FALSE | F23: Independence Day
B24: 46250 | C24: Sun | D24: 3 | E24: FALSE
B25: 46251 | C25: Mon | D25: 4 | E25: TRUE
B26: 46252 | C26: Tue | D26: 4 | E26: TRUE
B27: 46253 | C27: Wed | D27: 4 | E27: TRUE
B28: 46254 | C28: Thu | D28: 4 | E28: TRUE
B29: 46255 | C29: Fri | D29: 4 | E29: TRUE
B30: 46256 | C30: Sat | D30: 4 | E30: FALSE
B31: 46257 | C31: Sun | D31: 4 | E31: FALSE
B32: 46258 | C32: Mon | D32: 5 | E32: TRUE
B33: 46259 | C33: Tue | D33: 5 | E33: TRUE
B34: 46260 | C34: Wed | D34: 5 | E34: TRUE
B35: 46261 | C35: Thu | D35: 5 | E35: TRUE
... B42: 46268 | C42: Thu | D42: 6 | E42: TRUE
B43: 46269 | C43: Fri | D43: 6 | E43: FALSE | F43: Janmashtami
B44: 46270 | C44: Sat | D44: 6 | E44: FALSE
B45: 46271 | C45: Sun | D45: 6 | E45: FALSE
B46: 46272 | C46: Mon | D46: 7 | E46: TRUE
B47: 46273 | C47: Tue | D47: 7 | E47: TRUE
B48: 46274 | C48: Wed | D48: 7 | E48: TRUE
B49: 46275 | C49: Thu | D49: 7 | E49: TRUE
B50: 46276 | C50: Fri | D50: 7 | E50: TRUE
B51: 46277 | C51: Sat | D51: 7 | E51: FALSE
B52: 46278 | C52: Sun | D52: 7 | E52: FALSE
B53: 46279 | C53: Mon | D53: 8 | E53: TRUE
...

Sheet Non-Working Days
B2: Name | C2: Date
B3: Independence Day | C3: 46249
B4: Janmashtami | C4: 46269
B5: Mahatma Gandhi's Birthday | C5: 46297
B6: Dussehra | C6: 46315
B7: Maharishi Valmiki Birthday | C7: 46321
B8: Diwali | C8: 46334
B9: Birthday of Shri Guru Nanak Dev Ji | C9: 46350
B10: Christmas | C10: 46381
B11: Mid-Semester Break Day 1 | C11: 46332
B12: Mid-Semester Break Day 2 | C12: 46333
B13: Mid-Semester Break Day 3 | C13: 46334
B14: Mid-Semester Break Day 4 | C14: 46335
... B21: Pre-Winter Break Day5 | C21: 46366

Sheet Events
B2: DATE | C2: Event Name | D2: Event Type
B3: 46296 | C3: Mid-Sem Exams | D3: Exam
B4: 46297 | C4: Mid-Sem Exams | D4: Exam
B5: 46298 | C5: Mid-Sem Exams | D5: Exam
B6: 46299 | C6: Mid-Sem Exams | D6: Exam
B7: 46300 | C7: Mid-Sem Exams | D7: Exam
B8: 46301 | C8: Mid-Sem Exams | D8: Exam
B9: 46302 | C9: Mid-Sem Exams | D9: Exam
B10: 46303 | C10: Mid-Sem Exams | D10: Exam
B11: 46325 | C11: Pecfest Day 1 | D11: Fest
B12: 46326 | C12: Pecfest Day 2 | D12: Fest
B13: 46327 | C13: Pecfest Day 3 | D13: Fest
B14: 46352 | C14: End-Sem Exams | D14: Exam
... B23: 46361 | C23: End-Sem Exams | D23: Exam

Sheet Setting sheet
B2: Setting | C2: Value | E2: Months | F2: Month Number
B3: Semester Start | C3: 46230 | E3: July | F3: 7
B4: Semester End | C4: 46366 | E4: August | F4: 8
E5: September | F5: 9
E6: October | F6: 10
E7: November | F7: 11
E8: December | F8: 12
